## Билет 09 Исключения — основы 
Автор: Михаил Лопатин


### Предусловия и постусловия конструктора и деструктора, инвариант объекта

???

### Как отличить "ошибки программирования" (undefined behavior, нарушение инвариантов, невозможно предсказать поведение после) и "ошибки окружения" (некорректный ввод пользователя, теоретически можно предсказать и обработать), разные стратегии обработки для двух видов ошибок

    1. Ошибки программирования: любой UB, нарушение инварианта (двоичный поиск, состояние класса), нарушения контракта.
`
void foo(const char *s) {
    printf("%s\n", s);  // Некорректный s.
}
`
    * Лучше выявлять на стадии тестирования.
    * Обычно видны не сразу, а через какое-то время.
    * Можно пробовать проверять и детектировать (например, vector::at вместо vector::operator[]), но не задетектирует всё (потому что баги) и неясно, что делать после обнаружения (мало в чём можно быть уверенным).
    * Если случилось, то никаких гарантий, all bets are off. Баг в программе точно есть, причём неизвестный, могло упасть где угодно.

    2. "Ошибки окружения": некорректный ввод пользователя, файл не найден, оборвалось сетевое соединение...

    * Могут произойти независимо от программы.
    * Лучше обрабатывать.
    * Например, клиент Telegram должен быстро работать, даже если сервер внезапно отвалился. Переподключиться? Держать ещё одно соединение в запасе? Надо думать.
    * Не хватило прав доступа — может, наоборот, не сообщать пользователю, зато сообщить администратору.

Бывают пограничные ситуации в разных контекстах.

    * На хороших контестах гарантируется, что ввод корректен.
    * А что если кончился стэк/память/место на диске?
        * Место на диске: можно забить, можно почистить свой собственный кэш.
        * Память: а если при обработке потребуется ещё память?
        * Не удалась запись в файл: могут быть разные требования к чат-клиенту (который может всё скачать с сервера) и самому серверу (которому надо как-то восстанавливаться и централизованно сообщать "жёсткий диск сломался").
    * Нарушен инвариант структуры — проблема. А вот если мы её перед этим считывали по сети, то, может, это попытка взлома и надо залогировать и пропустить запрос.

Про каждую ошибку в программе надо думать:

    * Что случится, когда произойдёт? (не "если")
    * Можно ли с ней сделать что-то разумное?
    
Почти всегда можно залогировать ошибку для разработчика.

    * Уронить процесс целиком. Самое безопасное при ошибках программирования. Хотя тоже может нарушить инварианты (например, файл не до конца записали). Можно ещё перед этим позвонить домой и отправить багрепорт. А потом немедленно упасть, даже если кажется, что всё хорошо.
    * Уронить кусок процесса. Только если не ошибка программирования (хотя в Java/Python с изоляцией получше). Например, мы сервер и порвалось соединение с клиентом.
    * Как-то обработать: например, попробовать другой адрес для подключения к серверу.
    * Сообщить пользователю и попросить что-нибудь сделать: "файл не найден, выберите другой".
        * Важно понимать, что пользователь далеко не всегда что-то может сделать. О каких ошибках и как сообщать пользователю — отдельный вопрос.

Проще и надёжнее всего уронить программу целиком.

Нет серебрянной пули для обработки ошибок: это такая же часть спецификации программы, над которой надо хорошо думать заранее и отдельно реализовывать.

Например, On Error Resume Next писать не надо никогда.

### Примеры обработки разных видов ошибок без исключений: assert, коды возврата

## C-style, глобальная переменная и возвращаемое значение 

`
void read_people() {
    FILE *f = fopen(filename "r");
    if (!f) {  // Не удалось открыть файл — вернули nullptr.
        printf("Unable to open file\n");
        return;
    }
    // ...
    fclose(f);
}
`
Можно попробовать разобраться поподробнее:

    * EAССES — не хватило каких-то прав доступа (на файл, на папку выше, на создание файла в режиме w...). Самое популярное. Пользователю придётся проверять все папки в иерархии, права процесса...
    * EISDIR — попытались открыть папку как файл на запись.

Пример под Linux: int chdir(const char *path). Возвращает 0 или -1, а дальше смотрим в глобальном errno код.

Разумеется, так нельзя вызывать несколько функций подряд (потому что errno затёрлось) и плохо работать с многопоточностью (надо заводить errno на поток).

Бывают костыли вроде perror (вывести на экран последнюю ошибку).

## C-style, код ошибки

`
int sqlite3_open(
  const char *filename,   /* Database filename (UTF-8) */
  sqlite3 **ppDb          /* OUT: SQLite db handle */
);
`
Функция сразу возвращает код ошибки. А возвращаемое значение пишет по указателю.

Всё ещё надо проверять и не очень удобно.

### Исключения: try, catch, throw (синтаксис, и для новых исключений, и для перебрасывания "текущего"), где что ставить для обработки ошибок

Призваны решить следующие проблемы кодов возврата:

    * Захламляется код, даже если мы не умеем обрабатывать ошибку.
    * Перемешаны happy path/sad path.

Идея:

    * В месте возникновения "кидаем" исключение throw:
    * В промежуточных функциях ничего не делаем
    * Там, где понимаем, что можно сделать, ловим и обрабатываем.
`
struct invalid_vector_format {};
std::vector<int> readVector() {
    int n;
    if (!(cin >> n)) {
        throw invalid_vector_format();
    }
    std::vector<int> result(n); // может кинуть исключение.
    for (int i = 0; i < n; i++) {
        if (!(cin >> result[i])) {
            throw invalid_vector_format(); // кинул исключение, знаем, что кто-нибудь поймает.
        }
    }
    return result;
}
void solve() {
    std::vector<int> a = readVector();
    std::vector<int> b = readVector();  // исключение пролетело насквозь
    // вычисления
    writeAnswer(answer);
}
int main() {
    try {
        char *x = malloc(10);
        solve(); // исключение пролетело насквозь
        free(x);
    } catch (invalid_vector_format &err) {
        printf("Invalid vector format: %s\n", err.what());
    }
}
`

### Вложенные try/catch, несколько catch подряд и почему важно ловить по ссылке

`
try {
    // вызвали функцию, в которой
    try {
        throw Bar();
    } catch (Foo &err) {
    }
} catch (Bar &err) {
}
`
Проверяется от внутренних к внешним (в том числе сквозь стэк) и в каждом try пробуем за'bind'ить сверху вниз.

Если внутри catch исключение, то оно вылетает во внешний try.


    * Ловят всегда по ссылке, потому что активно используется иерархия и мы не хотим слайсинг. Синтаксис в catch — просто инициализация (как переменная/параметр).
    * Кидают объекты из отдельной иерархии (чтобы можно быть ловить по типу однозначно), причём выделенные "на стеке" (не в куче).
    * Исключения конкретно в C++ предназначены для обработки исключительных ситуаций, которые возникают редко. Компилиторы оптимизируются под happy path, а переключение на sad path может очень сильно тормозить.


### Stack unwinding (раскрутка стэка) и уничтожение локальных ресурсов

`
struct invalid_vector_format {};
std::vector<int> readVector() {
    int n;
    if (!(cin >> n)) {
        throw invalid_vector_format();
    }
    std::vector<int> result(n); // может кинуть исключение.
    for (int i = 0; i < n; i++) {
        if (!(cin >> result[i])) {
            throw invalid_vector_format(); // кинул исключение, знаем, что кто-нибудь поймает.
        }
    }
    return result;
}
void solve() {
    std::vector<int> a = readVector();
    std::vector<int> b = readVector();  // исключение пролетело насквозь
    // вычисления
    writeAnswer(answer);
}
int main() {
    try {
        char *x = malloc(10);
        solve(); // исключение пролетело насквозь
        free(x);
    } catch (invalid_vector_format &err) {
        printf("Invalid vector format: %s\n", err.what());
    }
}
`

Тут надо аккуратно уничтожить все векторы. Язык это и сделает: при выходе из блока (в т.ч. функции) уничтожает все локальные переменные. Это называется "раскрутка стэка" (stack unwinding).

При этом char *x утечёт, как обычно. Мораль: используйте деструкторы, как в std::vector. Или надо ловить вообще все исключения, а потом аккуратно разбираться, кого надо почистить, это неприятно.

### Идиома Resource Acquisition Is Initialization (RAII)

Если кончилась память в момент выделения вектора, вылетит стандартное исключение std::bad_alloc.

И вектор нельзя будет использовать. Даже синтаксически:

`
try {
    std::vector<int> a(1000000);
    ...
} catch (std::bad_alloc&) {
    ...
}
`
Наконец, расшифровка RAII: resource acquisition is initialization. Конструктор должен полностью проинициализировать класс и убедиться во всех инвариантах. А если не смог — кидаем исключение.

### Примеры исключений из стандартной библиотеки (std::exception и его наследники, bad_alloc)


    * UB и деление на ноль не кидают ничего. В Java есть специальный NullPointerException и ArithmeticException, но что с ними делать — вообще неясно.
    * std::exception — базовый класс для всех из STL (обычно свои тоже к нему приписывают). Реализует virtual const char *what() const.
        * std::logic_error — условно "ошибки программиста". Здесь std::invalid_argument, std::out_of_range и ещё.
        * std::runtime_error — условно "ошибки окружения". Есть наследник std::system_error, а у него наследник ios_base::failure (ошибки ввода-вывода).
    * new Foo() кидает std::bad_alloc, если не удалось выделить память. Но что с ним делать?
    * vector::at кидает std::out_of_range. Но что с ним делать?
    * std::stoi кидает std::invalid_argument (не число) или std::out_of_range (число не влезет).
    * <iostream> не кидает по умолчанию (надо проверять флаги), но можно включить режим.

Можно добавлять свои классы, а дальше ловить:

`
struct Foo {};
struct Bar : Foo {};
...
try {
} catch (Bar &err) {
} catch (Foo &err) {
} catch (std::exception &e) {
}
`
* catch (...) Ловит исключения любого типа, проанализировать текущее нельзя. Но можно перекинуть: throw; (работает в любом блоке). Всё ещё не ловит деление на ноль и прочие UB!
